28/Sep/2023 12:43:45 ERROR D:\GoncharenkoOA\Ucheba\Python\Django\Project\NewsPaper\venv\lib\site-packages\django\utils\log.py Internal Server Error: /news/13/update/ (<class 'smtplib.SMTPAuthenticationError'>, SMTPAuthenticationError(535, b'5.7.8 Error: authentication failed: Invalid user or password! 1695897824-fhOFn0jDU0U0'), <traceback object at 0x00000154DFC1B540>)
Traceback (most recent call last):
  File "D:\GoncharenkoOA\Ucheba\Python\Django\Project\NewsPaper\venv\lib\site-packages\django\core\handlers\exception.py", line 55, in inner
    response = get_response(request)
  File "D:\GoncharenkoOA\Ucheba\Python\Django\Project\NewsPaper\venv\lib\site-packages\django\core\handlers\base.py", line 197, in _get_response
    response = wrapped_callback(request, *callback_args, **callback_kwargs)
  File "D:\GoncharenkoOA\Ucheba\Python\Django\Project\NewsPaper\venv\lib\site-packages\django\views\generic\base.py", line 104, in view
    return self.dispatch(request, *args, **kwargs)
  File "D:\GoncharenkoOA\Ucheba\Python\Django\Project\NewsPaper\venv\lib\site-packages\django\views\generic\base.py", line 143, in dispatch
    return handler(request, *args, **kwargs)
  File "D:\GoncharenkoOA\Ucheba\Python\Django\Project\NewsPaper\venv\lib\site-packages\django\views\generic\edit.py", line 208, in post
    return super().post(request, *args, **kwargs)
  File "D:\GoncharenkoOA\Ucheba\Python\Django\Project\NewsPaper\venv\lib\site-packages\django\views\generic\edit.py", line 153, in post
    return self.form_valid(form)
  File "D:\GoncharenkoOA\Ucheba\Python\Django\Project\NewsPaper\venv\lib\site-packages\django\views\generic\edit.py", line 135, in form_valid
    self.object = form.save()
  File "D:\GoncharenkoOA\Ucheba\Python\Django\Project\NewsPaper\venv\lib\site-packages\django\forms\models.py", line 543, in save
    self._save_m2m()
  File "D:\GoncharenkoOA\Ucheba\Python\Django\Project\NewsPaper\venv\lib\site-packages\django\forms\models.py", line 524, in _save_m2m
    f.save_form_data(self.instance, cleaned_data[f.name])
  File "D:\GoncharenkoOA\Ucheba\Python\Django\Project\NewsPaper\venv\lib\site-packages\django\db\models\fields\related.py", line 1956, in save_form_data
    getattr(instance, self.attname).set(data)
  File "D:\GoncharenkoOA\Ucheba\Python\Django\Project\NewsPaper\venv\lib\site-packages\django\db\models\fields\related_descriptors.py", line 1236, in set
    self.add(*new_objs, through_defaults=through_defaults)
  File "D:\GoncharenkoOA\Ucheba\Python\Django\Project\NewsPaper\venv\lib\site-packages\django\db\models\fields\related_descriptors.py", line 1137, in add
    self._add_items(
  File "D:\GoncharenkoOA\Ucheba\Python\Django\Project\NewsPaper\venv\lib\site-packages\django\db\models\fields\related_descriptors.py", line 1447, in _add_items
    signals.m2m_changed.send(
  File "D:\GoncharenkoOA\Ucheba\Python\Django\Project\NewsPaper\venv\lib\site-packages\django\dispatch\dispatcher.py", line 176, in send
    return [
  File "D:\GoncharenkoOA\Ucheba\Python\Django\Project\NewsPaper\venv\lib\site-packages\django\dispatch\dispatcher.py", line 177, in <listcomp>
    (receiver, receiver(signal=self, sender=sender, **named))
  File "D:\GoncharenkoOA\Ucheba\Python\Django\Project\NewsPaper\NewsPaper\news\signals.py", line 39, in notify_about_new_post
    send_notifications(instance.preview(), instance.pk, instance.title, subscribers)
  File "D:\GoncharenkoOA\Ucheba\Python\Django\Project\NewsPaper\NewsPaper\news\signals.py", line 26, in send_notifications
    msg.send()
  File "D:\GoncharenkoOA\Ucheba\Python\Django\Project\NewsPaper\venv\lib\site-packages\django\core\mail\message.py", line 298, in send
    return self.get_connection(fail_silently).send_messages([self])
  File "D:\GoncharenkoOA\Ucheba\Python\Django\Project\NewsPaper\venv\lib\site-packages\django\core\mail\backends\smtp.py", line 127, in send_messages
    new_conn_created = self.open()
  File "D:\GoncharenkoOA\Ucheba\Python\Django\Project\NewsPaper\venv\lib\site-packages\django\core\mail\backends\smtp.py", line 94, in open
    self.connection.login(self.username, self.password)
  File "C:\Users\LENOVO\AppData\Local\Programs\Python\Python310\lib\smtplib.py", line 750, in login
    raise last_exception
  File "C:\Users\LENOVO\AppData\Local\Programs\Python\Python310\lib\smtplib.py", line 739, in login
    (code, resp) = self.auth(
  File "C:\Users\LENOVO\AppData\Local\Programs\Python\Python310\lib\smtplib.py", line 662, in auth
    raise SMTPAuthenticationError(code, resp)
smtplib.SMTPAuthenticationError: (535, b'5.7.8 Error: authentication failed: Invalid user or password! 1695897824-fhOFn0jDU0U0')
28/Sep/2023 12:43:45 ERROR D:\GoncharenkoOA\Ucheba\Python\Django\Project\NewsPaper\venv\lib\site-packages\django\core\servers\basehttp.py "POST /news/13/update/ HTTP/1.1" 500 185006 None
